{"name": "Тест Ошибка при авторизации под несуществующим пользователем", "status": "passed", "start": 1738680782477, "stop": 1738680782944, "uuid": "bdf15291-d935-4e37-abb1-d118658b1e79", "historyId": "dc561881fc51df78d89a2a63cc5f127d", "testCaseId": "dc561881fc51df78d89a2a63cc5f127d", "fullName": "tests.test_login_courier.TestLoginCourier#test_auth_with_non_existent_user", "labels": [{"name": "parentSuite", "value": "tests"}, {"name": "suite", "value": "test_login_courier"}, {"name": "subSuite", "value": "TestLoginCourier"}, {"name": "host", "value": "pyreva.local"}, {"name": "thread", "value": "41910-MainThread"}, {"name": "framework", "value": "pytest"}, {"name": "language", "value": "cpython3"}, {"name": "package", "value": "tests.test_login_courier"}]}