{"name": "Тест Ошибка при авторизации под несуществующим пользователем", "status": "passed", "start": 1738680535464, "stop": 1738680535899, "uuid": "ae0d7904-55ce-4a71-942c-6bc153f9f849", "historyId": "dc561881fc51df78d89a2a63cc5f127d", "testCaseId": "dc561881fc51df78d89a2a63cc5f127d", "fullName": "tests.test_login_courier.TestLoginCourier#test_auth_with_non_existent_user", "labels": [{"name": "parentSuite", "value": "tests"}, {"name": "suite", "value": "test_login_courier"}, {"name": "subSuite", "value": "TestLoginCourier"}, {"name": "host", "value": "pyreva.local"}, {"name": "thread", "value": "41819-MainThread"}, {"name": "framework", "value": "pytest"}, {"name": "language", "value": "cpython3"}, {"name": "package", "value": "tests.test_login_courier"}]}